<?xml version="1.0" ?>
<robot name="omnidirectional" xmlns:xacro="http://ros.org/wiki/xacro">

    <xacro:property name="base_length" value="0.25" />
    <xacro:property name="base_width" value="0.15" />
    <xacro:property name="base_height" value="0.1" />
    <xacro:property name="wheel_radius" value="0.06" />
    <xacro:property name="wheel_length" value="0.05" />
    
    <link name="base_footprint"/>

    <joint name="base_joint" type="fixed">
        <parent link="base_footprint"/>
        <child link="base_link"/>
        <origin xyz="0 0 0.095" rpy="0 0 0"/>
    </joint>

    <link name="base_link">
        <visual>
            <origin xyz="0.0 0.0 0.0" rpy="0 0 0" />
            <geometry>
                <mesh filename="package://omnidirectional_description/meshes/X3/base_link.STL"/>
            </geometry>
            <material name="Green">
                <color rgba="0 0.7 0 1" />
            </material>
        </visual>
        <collision>
            <origin xyz="0.0 0.0 -0.05" rpy="0 0 0" />
            <geometry>
                <box size="0.25 0.15 0.095" />
            </geometry>
        </collision>
        <inertial>
            <origin xyz="0 0 0" rpy="0 0 0"/>
            <mass value="1"/>
            <inertia ixx="1.0" ixy="0.0" ixz="0.0" 
                iyy="1.0" iyz="0.0" izz="1.0"/>
        </inertial>
    </link>

    <link name="wheel_left_front">
        <visual>
            <origin xyz="0.0 0.0 0.0" rpy="0 0 0" />
            <geometry>
                <mesh filename="package://omnidirectional_description/meshes/X3/front_left_wheel.STL"/>
            </geometry>
            <material name="Grey">
                <color rgba="0.1 0.1 0.1 1.0" />
            </material>
        </visual>
        <collision>
            <origin xyz="0.0 0.0 0.0" rpy="0 0 0" />
            <geometry>
                <cylinder length="0.05" radius="0.06"/>
            </geometry>
        </collision>
        <inertial>
            <origin xyz="0 0 0" rpy="0 0 0"/>
            <mass value="1"/>
            <inertia ixx="1.0" ixy="0.0" ixz="0.0" 
                iyy="1.0" iyz="0.0" izz="1.0"/>
        </inertial>
    </link>

    <joint name="wheel_left_front_joint" type="continuous">
        <origin xyz="0.1 0.1 -0.035" rpy="1.5708 0  0" />
        <parent link="base_link" />
        <child link="wheel_left_front" />
        <axis xyz="0 0 1" />
    </joint>

    <link name="wheel_rigth_front">
        <visual>
            <origin xyz="0.0 0.0 0.0" rpy="0 0 0" />
            <geometry>
                <mesh filename="package://omnidirectional_description/meshes/X3/front_right_wheel.STL"/>
            </geometry>
            <material name="Grey">
                <color rgba="0.1 0.1 0.1 1.0" />
            </material>
        </visual>
        <collision>
            <origin xyz="0.0 0.0 0.0" rpy="0 0 0" />
            <geometry>
                <cylinder length="0.05" radius="0.06"/>
            </geometry>
        </collision>
        <inertial>
            <origin xyz="0 0 0" rpy="0 0 0"/>
            <mass value="1"/>
            <inertia ixx="1.0" ixy="0.0" ixz="0.0" 
                iyy="1.0" iyz="0.0" izz="1.0"/>
        </inertial>
    </link>

    <joint name="wheel_rigth_front_joint" type="continuous">
        <origin xyz="0.1 -0.1 -0.035" rpy="1.5708 0  0" />
        <parent link="base_link" />
        <child link="wheel_rigth_front" />
        <axis xyz="0 0 1" />
    </joint>

    <link name="wheel_left_back">
        <visual>
            <origin xyz="0.0 0.0 0.0" rpy="0 0 0" />
            <geometry>
                <mesh filename="package://omnidirectional_description/meshes/X3/back_left_wheel.STL"/>
            </geometry>
            <material name="">
                <color rgba="0.1 0.1 0.1 1.0" />
            </material>
        </visual>
        <collision>
            <origin xyz="0.0 0.0 0.0" rpy="0 0 0" />
            <geometry>
                <cylinder length="0.05" radius="0.06"/>
            </geometry>
        </collision>
        <inertial>
            <origin xyz="0 0 0" rpy="0 0 0"/>
            <mass value="1"/>
            <inertia ixx="1.0" ixy="0.0" ixz="0.0" 
                iyy="1.0" iyz="0.0" izz="1.0"/>
        </inertial>
    </link>

    <joint name="wheel_left_back_joint" type="continuous">
        <origin xyz="-0.1 0.1 -0.035" rpy="1.5708 0  0" />
        <parent link="base_link" />
        <child link="wheel_left_back" />
        <axis xyz="0 0 1" />
    </joint>

    <link name="wheel_rigth_back">
        <visual>
            <origin xyz="0.0 0.0 0.0" rpy="0 0 0" />
            <geometry>
                <mesh filename="package://omnidirectional_description/meshes/X3/back_right_wheel.STL"/>
            </geometry>
            <material name="Grey">
                <color rgba="0.1 0.1 0.1 1.0" />
            </material>
        </visual>
        <collision>
            <origin xyz="0.0 0.0 0.0" rpy="0 0 0" />
            <geometry>
                <cylinder length="0.05" radius="0.06"/>
            </geometry>
        </collision>
        <inertial>
            <origin xyz="0 0 0" rpy="0 0 0"/>
            <mass value="1"/>
            <inertia ixx="1.0" ixy="0.0" ixz="0.0" 
                iyy="1.0" iyz="0.0" izz="1.0"/>
        </inertial>
    </link>

    <joint name="wheel_rigth_back_joint" type="continuous">
        <origin xyz="-0.1 -0.1 -0.035" rpy="1.5708 0  0" />
        <parent link="base_link" />
        <child link="wheel_rigth_back" />
        <axis xyz="0 0 1" />
    </joint>


    <!--
    <link name="lidar_link">
            <visual>
                <geometry>
                    <cylinder radius="0.05" length="0.05" />
                </geometry>
                <origin xyz="0 0 0" rpy="0 0 0" />
                <material name="grey" />
            </visual>
            <collision>
                <geometry>
                    <cylinder radius="0.1" length="0.05" />
                </geometry>
                    <origin xyz="0 0 0" rpy="0 0 0" />
            </collision>
            <inertial>
                <origin xyz="0 0 0" rpy="0 0 0" />
                <mass value="0.1" />
                <inertia ixx="0.1" ixy="0" ixz="0"
                        iyy="0.1" iyz="0"
                        izz="0.1" />
            </inertial> 
    </link>

    <link name="lidar_sensor" />

    <joint name="lidar_joint" type="fixed" >
        <parent link="base_link" />
        <child link="lidar_link" />
        <origin xyz="0 0 0.075" rpy="0 0 0" />
    </joint>

    <joint name="lidar_sensor_joint" type="fixed" >
        <parent link="lidar_link" />
        <child link="lidar_sensor" />
        <origin xyz="0 0 0" rpy="0 0 0" />
    </joint>

    <gazebo reference="lidar_link" >
        <material>Gazebo/Blue</material>
    </gazebo>

    <gazebo reference="lidar_sensor">
        <sensor type="ray" name="lidar">
            <pose>0 0 0 0 0 0</pose>
            <visualize>true</visualize>
            <always_on>true</always_on>
            <update_rate>15</update_rate>
            <ray>
                <scan>
                    <horizontal>
                        <samples>360</samples>
                        <resolution>1</resolution>
                        <min_angle>-3.14</min_angle>
                        <max_angle>3.14</max_angle>
                    </horizontal>
                </scan>
                <range>
                    <min>0.15</min>
                    <max>1.5</max>
                    <resolution>0.017453</resolution>
                </range>
                <noise>
                    <type>gaussian</type>
                    <mean>0.0</mean>
                    <stddev>0.01</stddev>
                </noise>
            </ray>
            <plugin name="laser_plugin" filename="libgazebo_ros_ray_sensor.so">
                <ros>
                    <remapping>~/out:=scan</remapping>
                </ros>
                <output_type>sensor_msgs/LaserScan</output_type>
                <frame_name>lidar_sensor</frame_name>
            </plugin>
        </sensor>
    </gazebo>
    -->
   
</robot>